<?xml version="1.0" encoding="utf-8"?>
<robot name="drone" xmlns:xacro="http://ros.org/wiki/xacro">
  <link
    name="base_link">
    <inertial>
      <origin
        xyz="0 0 0"
        rpy="0 0 0" />
      <mass
        value="1.49" />
      <inertia
        ixx="0.0785"
        ixy="0"
        ixz="0"
        iyy="0.0785"
        iyz="0"
        izz="0.105" />
    </inertial>
    <visual>
      <origin
        xyz="0 0 0"
        rpy="0 0 0" />
      <geometry>
        <mesh
          filename="file://$(find smcmpcquad)/models/meshes/base_link.STL" />
      </geometry>
      <material
        name="">
        <color
          rgba="0.752941176470588 0.752941176470588 0.752941176470588 1" />
      </material>
    </visual>
    <collision>
      <origin
        xyz="0 0 -0.05"
        rpy="0 0 0" />
      <geometry>
         <box size = "0.15 0.15 0.2" />
      </geometry>
    </collision>
  </link>
  <link
    name="propbackright">
    <inertial>
      <origin
        xyz="0 0 0"
        rpy="0 0 0" />
      <mass
        value="0.09" />
      <inertia
        ixx="0.00004"
        ixy="0"
        ixz="0"
        iyy="0.00004"
        iyz="0"
        izz="0.000025" />
    </inertial>
    <visual>
      <origin
        xyz="0 0 0"
        rpy="0 0 0" />
      <geometry>
        <mesh
          filename="file://$(find smcmpcquad)/models/meshes/propeller_0.STL" />
      </geometry>
      <material
        name="">
        <color
          rgba="0.294117647058824 0.294117647058824 0.294117647058824 1" />
      </material>
    </visual>
    <collision>
      <origin
        xyz="0 0 0"
        rpy="0 0 0" />
      <geometry>
        <mesh
          filename="file://$(find smcmpcquad)/models/meshes/propeller_0.STL" />
      </geometry>
    </collision>
  </link>
  <joint
    name="pbr"
    type="continuous">
    <origin
      xyz="-0.159 -0.159 0.065"
      rpy="0 0 -1.5708" />
    <parent
      link="base_link" />
    <child
      link="propbackright" />
    <axis
      xyz="0 0 -1" />
  </joint>
  <link
    name="propbackleft">
    <inertial>
      <origin
        xyz="0 0 0"
        rpy="0 0 0" />
      <mass
        value="0.09" />
      <inertia
        ixx="0.00004"
        ixy="0"
        ixz="0"
        iyy="0.00004"
        iyz="0"
        izz="0.000025" />
    </inertial>
    <visual>
      <origin
        xyz="0 0 0"
        rpy="0 0 0" />
      <geometry>
        <mesh
          filename="file://$(find smcmpcquad)/models/meshes/propeller_1.STL" />
      </geometry>
      <material
        name="">
        <color
          rgba="0.294117647058824 0.294117647058824 0.294117647058824 1" />
      </material>
    </visual>
    <collision>
      <origin
        xyz="0 0 0"
        rpy="0 0 0" />
      <geometry>
        <mesh
          filename="file://$(find smcmpcquad)/models/meshes/propeller_1.STL" />
      </geometry>
    </collision>
  </link>
  <joint
    name="pbl"
    type="continuous">
    <origin
      xyz="-0.159 0.159 0.065"
      rpy="0 0 -1.5708" />
    <parent
      link="base_link" />
    <child
      link="propbackleft" />
    <axis
      xyz="0 0 -1" />
  </joint>
  <link
    name="propfrontright">
    <inertial>
      <origin
        xyz="0 0 0"
        rpy="0 0 0" />
      <mass
        value="0.09" />
      <inertia
        ixx="0.00004"
        ixy="0"
        ixz="0"
        iyy="0.00004"
        iyz="0"
        izz="0.000025" />
    </inertial>
    <visual>
      <origin
        xyz="0 0 0"
        rpy="0 0 0" />
      <geometry>
        <mesh
          filename="file://$(find smcmpcquad)/models/meshes/propeller_1.STL" />
      </geometry>
      <material
        name="">
        <color
          rgba="0.294117647058824 0.294117647058824 0.294117647058824 1" />
      </material>
    </visual>
    <collision>
      <origin
        xyz="0 0 0"
        rpy="0 0 0" />
      <geometry>
        <mesh
          filename="file://$(find smcmpcquad)/models/meshes/propeller_1.STL" />
      </geometry>
    </collision>
  </link>
  <joint
    name="pfr"
    type="continuous">
    <origin
      xyz="0.159 -0.159 0.065"
      rpy="0 0 -1.5708" />
    <parent
      link="base_link" />
    <child
      link="propfrontright" />
    <axis
      xyz="0 0 -1" />
  </joint>
  <link
    name="propfrontleft">
    <inertial>
      <origin
        xyz="0 0 0"
        rpy="0 0 0" />
      <mass
        value="0.09" />
      <inertia
        ixx="0.00004"
        ixy="0"
        ixz="0"
        iyy="0.00004"
        iyz="0"
        izz="0.000025" />
    </inertial>
    <visual>
      <origin
        xyz="0 0 0"
        rpy="0 0 0" />
      <geometry>
        <mesh
          filename="file://$(find smcmpcquad)/models/meshes/propeller_0.STL" />
      </geometry>
      <material
        name="">
        <color
          rgba="0.294117647058824 0.294117647058824 0.294117647058824 1" />
      </material>
    </visual>
    <collision>
      <origin
        xyz="0 0 0"
        rpy="0 0 0" />
      <geometry>
        <mesh
          filename="file://$(find smcmpcquad)/models/meshes/propeller_0.STL" />
      </geometry>
    </collision>
  </link>
  <joint
    name="pfl"
    type="continuous">
    <origin
      xyz="0.159 0.159 0.065"
      rpy="0 0 -1.5708" />
    <parent
      link="base_link" />
    <child
      link="propfrontleft" />
    <axis
      xyz="0 0 -1" />
  </joint>
  
  <gazebo>
    <plugin name="gazebo_ros_state" filename="libgazebo_ros_p3d.so">
      <ros>
        <namespace>/droneposition</namespace>
      </ros>
      <update_rate>200</update_rate> 
      <body_name>base_link</body_name> <!-- Link to track -->
      <frame_name>world</frame_name>
    </plugin>
  </gazebo>

  <!-- UAV plugin -->
  <gazebo>
  <plugin name="uavplugin" filename="/home/vanchung/dev_ws/install/smcmpcquad/lib/smcmpcquad/libuavplugin.so">
      <updateRate>200</updateRate> 
      <publishTf>true</publishTf>
      <rotorThrustCoeff>0.00025</rotorThrustCoeff>
      <rotorTorqueCoeff>0.000075</rotorTorqueCoeff>
    </plugin>
  </gazebo>

</robot>
